<?xml version="1.0" encoding="UTF-8"?>
<testng-results skipped="0" failed="2" total="3" passed="1">
  <reporter-output>
  </reporter-output>
  <suite name="Default suite" duration-ms="28246" started-at="2015-11-23T07:45:31Z" finished-at="2015-11-23T07:46:00Z">
    <groups>
    </groups>
    <test name="Default test" duration-ms="28246" started-at="2015-11-23T07:45:31Z" finished-at="2015-11-23T07:46:00Z">
      <class name="contaazul.exercises.Exercise2">
        <test-method status="PASS" signature="acessarMenuVendas()[pri:0, instance:contaazul.exercises.Exercise2@79879aa5]" name="acessarMenuVendas" duration-ms="15503" started-at="2015-11-23T04:45:31Z" finished-at="2015-11-23T04:45:47Z">
          <reporter-output>
          </reporter-output>
        </test-method> <!-- acessarMenuVendas -->
        <test-method status="FAIL" signature="novaVenda()[pri:0, instance:contaazul.exercises.Exercise2@79879aa5]" name="novaVenda" duration-ms="12718" started-at="2015-11-23T04:45:47Z" finished-at="2015-11-23T04:46:00Z">
          <exception class="java.lang.AssertionError">
            <message>
              <![CDATA[expected [ foi criada com sucesso.] but found []]]>
            </message>
            <full-stacktrace>
              <![CDATA[java.lang.AssertionError: expected [ foi criada com sucesso.] but found []
	at org.testng.Assert.fail(Assert.java:94)
	at org.testng.Assert.failNotEquals(Assert.java:496)
	at org.testng.Assert.assertEquals(Assert.java:125)
	at org.testng.Assert.assertEquals(Assert.java:178)
	at org.testng.Assert.assertEquals(Assert.java:188)
	at contaazul.pages.VendaPage.salvarVenda(VendaPage.java:93)
	at contaazul.exercises.Exercise2.novaVenda(Exercise2.java:42)
	at sun.reflect.NativeMethodAccessorImpl.invoke0(Native Method)
	at sun.reflect.NativeMethodAccessorImpl.invoke(NativeMethodAccessorImpl.java:57)
	at sun.reflect.DelegatingMethodAccessorImpl.invoke(DelegatingMethodAccessorImpl.java:43)
	at java.lang.reflect.Method.invoke(Method.java:606)
	at org.testng.internal.MethodInvocationHelper.invokeMethod(MethodInvocationHelper.java:85)
	at org.testng.internal.Invoker.invokeMethod(Invoker.java:659)
	at org.testng.internal.Invoker.invokeTestMethod(Invoker.java:845)
	at org.testng.internal.Invoker.invokeTestMethods(Invoker.java:1153)
	at org.testng.internal.TestMethodWorker.invokeTestMethods(TestMethodWorker.java:125)
	at org.testng.internal.TestMethodWorker.run(TestMethodWorker.java:108)
	at org.testng.TestRunner.privateRun(TestRunner.java:771)
	at org.testng.TestRunner.run(TestRunner.java:621)
	at org.testng.SuiteRunner.runTest(SuiteRunner.java:357)
	at org.testng.SuiteRunner.runSequentially(SuiteRunner.java:352)
	at org.testng.SuiteRunner.privateRun(SuiteRunner.java:310)
	at org.testng.SuiteRunner.run(SuiteRunner.java:259)
	at org.testng.SuiteRunnerWorker.runSuite(SuiteRunnerWorker.java:52)
	at org.testng.SuiteRunnerWorker.run(SuiteRunnerWorker.java:86)
	at org.testng.TestNG.runSuitesSequentially(TestNG.java:1199)
	at org.testng.TestNG.runSuitesLocally(TestNG.java:1124)
	at org.testng.TestNG.run(TestNG.java:1032)
	at org.testng.remote.RemoteTestNG.run(RemoteTestNG.java:111)
	at org.testng.remote.RemoteTestNG.initAndRun(RemoteTestNG.java:204)
	at org.testng.remote.RemoteTestNG.main(RemoteTestNG.java:175)
]]>
            </full-stacktrace>
          </exception> <!-- java.lang.AssertionError -->
          <reporter-output>
          </reporter-output>
        </test-method> <!-- novaVenda -->
        <test-method status="FAIL" signature="validaVenda()[pri:0, instance:contaazul.exercises.Exercise2@79879aa5]" name="validaVenda" duration-ms="0" started-at="2015-11-23T04:46:00Z" finished-at="2015-11-23T04:46:00Z">
          <exception class="java.lang.NullPointerException">
            <full-stacktrace>
              <![CDATA[java.lang.NullPointerException
	at contaazul.pages.ResumoVendaPage.validaNumeroVenda(ResumoVendaPage.java:26)
	at contaazul.pages.VendaPage.validaVenda(VendaPage.java:99)
	at contaazul.exercises.Exercise2.validaVenda(Exercise2.java:47)
	at sun.reflect.NativeMethodAccessorImpl.invoke0(Native Method)
	at sun.reflect.NativeMethodAccessorImpl.invoke(NativeMethodAccessorImpl.java:57)
	at sun.reflect.DelegatingMethodAccessorImpl.invoke(DelegatingMethodAccessorImpl.java:43)
	at java.lang.reflect.Method.invoke(Method.java:606)
	at org.testng.internal.MethodInvocationHelper.invokeMethod(MethodInvocationHelper.java:85)
	at org.testng.internal.Invoker.invokeMethod(Invoker.java:659)
	at org.testng.internal.Invoker.invokeTestMethod(Invoker.java:845)
	at org.testng.internal.Invoker.invokeTestMethods(Invoker.java:1153)
	at org.testng.internal.TestMethodWorker.invokeTestMethods(TestMethodWorker.java:125)
	at org.testng.internal.TestMethodWorker.run(TestMethodWorker.java:108)
	at org.testng.TestRunner.privateRun(TestRunner.java:771)
	at org.testng.TestRunner.run(TestRunner.java:621)
	at org.testng.SuiteRunner.runTest(SuiteRunner.java:357)
	at org.testng.SuiteRunner.runSequentially(SuiteRunner.java:352)
	at org.testng.SuiteRunner.privateRun(SuiteRunner.java:310)
	at org.testng.SuiteRunner.run(SuiteRunner.java:259)
	at org.testng.SuiteRunnerWorker.runSuite(SuiteRunnerWorker.java:52)
	at org.testng.SuiteRunnerWorker.run(SuiteRunnerWorker.java:86)
	at org.testng.TestNG.runSuitesSequentially(TestNG.java:1199)
	at org.testng.TestNG.runSuitesLocally(TestNG.java:1124)
	at org.testng.TestNG.run(TestNG.java:1032)
	at org.testng.remote.RemoteTestNG.run(RemoteTestNG.java:111)
	at org.testng.remote.RemoteTestNG.initAndRun(RemoteTestNG.java:204)
	at org.testng.remote.RemoteTestNG.main(RemoteTestNG.java:175)
]]>
            </full-stacktrace>
          </exception> <!-- java.lang.NullPointerException -->
          <reporter-output>
          </reporter-output>
        </test-method> <!-- validaVenda -->
      </class> <!-- contaazul.exercises.Exercise2 -->
    </test> <!-- Default test -->
  </suite> <!-- Default suite -->
</testng-results>
